<mujoco model="hopper">
    <compiler angle="radian" />
    <option integrator="RK4" />
    <size njmax="500" nconmax="100" />
    <visual>
        <map znear="0.02" />
    </visual>
    <default>
        <geom rgba="1.0 0.5 0.0 1" />
    </default>
    <worldbody>
        <light pos="0 0 1.3" dir="0 0 -1" directional="true" cutoff="100" exponent="1" diffuse="1 1 1" specular="0.1 0.1 0.1" />
        <body name="torso" pos="0 0 1.25">
            <joint name="rootx" pos="0 0 -1.25" axis="1 0 0" type="slide" limited="false" armature="0" damping="0" />
            <joint name="rootz" pos="0 0 0" axis="0 0 1" type="slide" ref="1.25" limited="false" armature="0" damping="0" />
            <joint name="rooty" pos="0 0 0" axis="0 1 0" limited="false" type="hinge" armature="0" damping="0" />
            <geom name="torso_geom" size="0.05 0.2" type="capsule" friction="0.9 0.005 0.0001" />
            <body name="thigh" pos="0 0 -0.2">
                <joint name="thigh_joint" pos="0 0 0" type="hinge" axis="0 -1 0" range="-2.61799 0" />
                <geom name="thigh_geom" size="0.05 0.225" pos="0 0 -0.225" type="capsule" friction="0.9 0.005 0.0001" />
                <body name="leg" pos="0 0 -0.7">
                    <joint name="leg_joint" pos="0 0 0.25" type="hinge" axis="0 -1 0" range="-2.61799 0" />
                    <geom name="leg_geom" size="0.04 0.25" type="capsule" friction="0.9 0.005 0.0001" />
                    <body name="foot" pos="0.0 0 -0.25">
                        <joint name="foot_joint" pos="0 0 0.0" type="hinge" axis="0 -1 0" range="-0.785398 0.785398" />
                        <geom name="foot_geom" size="0.06 0.195" pos="0.06 0 0.0" quat="0.707107 0 -0.707107 0" type="capsule" friction="2 0.005 0.0001" />
                    </body>
                </body>
            </body>
        </body>
    </worldbody>
    <actuator>
        <general joint="thigh_joint" ctrlrange="-1 1" gear="200 0 0 0 0 0" />
        <general joint="leg_joint" ctrlrange="-1 1" gear="200 0 0 0 0 0" />
        <general joint="foot_joint" ctrlrange="-1 1" gear="200 0 0 0 0 0" />
    </actuator>
</mujoco>